Workbook

Sheet Receivables list
A1: Receiveabl List
A3: S.NO | B3: PARTY NAME | C3: BALANCE
A5: 1 | B5: Al Bayan Water | C5: ='Al Bayan Water '!F8 -> 0
A6: 2 | B6: Ab e Rose Water | C6: ='Ab e Rose Water'!F8 -> 27468
A7: 3 | B7: Aqua Musafi | C7: ='Aqua Musafi'!F25 -> 30578
A8: 4 | B8: Al Javaid Ice Factory | C8: ='Al Javed Ice Factory'!F10 -> 26550
A9: 5 | B9: Al Maida Water | C9: ='Al Maida Water'!F24 -> 35552
A10: 6 | B10: Ahmed N-One Water | C10: ='Ahmed N One water'!F52 -> 581570
A11: 8 | B11: Al Khidmat Lodhran | C11: ='Al Khidmat lodhran '!F10 -> 51024
A12: 9 | B12: Al Khidmat BWP | C12: ='Al Khidmat Bwp'!F23 -> 79945
A13: 10 | B13: Al Shafi Water | C13: ='Al Shafi Water (Younas sb)'!F20 -> 2150
A14: 11 | B14: Aqua Refine | C14: ='Aqua Refine '!G142 -> 350
A15: 12 | B15: Abshar Water | C15: ='Abshar Water'!F12 -> 15450
A16: 13 | B16: Aqua Marine | C16: ='Aqua Marine '!F10 -> 73127
A17: 14 | B17: Ab e Hayat Plus | C17: ='Ab e Hayat Plus'!F16 -> 253
A18: 15 | B18: Aqsa Water Chishti Sb | C18: ='Aqsa Water'!F9 -> 51181
A19: 16 | B19: Al Azam Water | C19: ='Al Azam Water'!F30 -> 95940
A20: 17 | B20: Aqua Santa | C20: ='Aqua Santa'!F8 -> 9684
A21: 18 | B21: Ahmed Ice Factory(LD) | C21: ='Ahmed Ice Factory '!F27 -> 106514
A22: 19 | B22: Aqua Shereen | C22: ='Aqua Shereen '!F8 -> 54965
A23: 20 | B23: Alien Water Lodhran | C23: ='Alien Water( Lodhran)'!F14 -> 11800
A24: 21 | B24: Alien Water Bwp | C24: ='Alien Water( Bwp)'!F10 -> 0
A25: 22 | B25: A.F Water | C25: ='A.F Water'!F10 -> 10351
A26: 23 | B26: Aswad Sb | C26: ='Aswad Sb'!F34 -> 1775
A27: 24 | B27: Asia Homeo Store | C27: ='Asia Homeyo Store'!F10 -> 11250
A28: 25 | B28: Ahsas Water | C28: ='Ahsas Water '!F8 -> 0
A29: 26 | B29: Al Subhan Water | C29: ='Al Subhan Water'!F12 -> 0
A30: 27 | B30: Barcly Water | C30: ='Barcly Water'!F77 -> 137250
A31: 28 | B31: Bling Water | C31: ='Bling Water'!F17 -> 32830
A32: 29 | B32: Bissmillah Senitary | C32: ='Bissimillah Senitary '!F8 -> 3624
A33: 30 | B33: BWP Water | C33: ='Bwp Water'!F10 -> 7415
A34: 31 | B34: Berg Water | C34: ='Berg Water'!F22 -> 0
A35: 32 | B35: BWMC | C35: =BWMC!F12 -> 1000
A36: 33 | B36: Chand Agro | C36: ='Chand Agro'!F69 -> 2500
A37: 34 | B37: Candy Water | C37: ='Candy Water'!F30 -> -2320
A38: 35 | B38: Clean And Clean | C38: ='Clean & Clean'!F13 -> 37270
A39: 36 | B39: Dar E Arqam | C39: ='Dar e Arqam '!F9 -> 0
A40: 37 | B40: Dr Aqua Water | C40: ='1'!F17 -> -164770
A41: 38 | B41: Ever Best | C41: ='Ever Best'!F8 -> 16664
A42: 39 | B42: Gysing Pak Water | C42: ='Gysing Pak Water'!F346 -> 298774
...

Sheet Aqua Refine 
A1: LEDGER
A3: Account Holder's Name | E3: Aqua Refine
A4: Pg # | C4: New Reg (96)
A5: Date | B5: Ref No. | C5: Description | D5: Description | E5: Debit | F5: Credit | G5: Balance
A6: 23/05/24 | B6: F1859 | C6: 1.5L Bottle,.. | F6: 25850 | G6: =F6-E6 -> 25850
A7: 23/05/24 | B7: F1876 | C7: 1.5L Shoper | F7: 6800 | G7: =G6-E7+F7 -> 32650
A8: 30/05/24 | B8: F1977 | C8: 30 mm Seal | F8: 5100 | G8: =G7-E8+F8 -> 37750
A9: 30/05/24 | B9: F1986 | C9: 1.5L Bottle,.. | F9: 56438 | G9: =G8-E9+F9 -> 94188
A10: 23/05/24 | C10: IBFT | E10: 40000 | G10: =G9-E10+F10 -> 54188
A11: 30/05/24 | C11: Cash in Hand | E11: 25000 | G11: =G10-E11+F11 -> 29188
A12: 45418 | B12: G58 | C12: 30 mm Caps,.. | F12: 7000 | G12: =G11-E12+F12 -> 36188 | BY12: 8330
A13: 45449 | C13: 1.5L Bottle Return 7/-@10.80 | E13: 5292 | G13: =G12-E13+F13 -> 30896
A14: 45632 | B14: G123 | C14: 1.5L Bottle,.. | F14: 43675 | G14: =G13-E14+F14 -> 74571
A15: 13/06/24 | C15: IBFT | E15: 50000 | G15: =G14-E15+F15 -> 24571
A16: 16/06/24 | B16: G182 | C16: 1.5L Bottle,.. | F16: 17190 | G16: =G15-E16+F16 -> 41761
A17: 20/6/24 | B17: G193 | C17: 500ml-Caps,1.5 Bottle-Caps,.. | F17: 9616 | G17: =G16-E17+F17 -> 51377
A18: 20/6/24 | B18: G195 | C18: 30mm Caps | F18: 5500 | G18: =G17-E18+F18 -> 56877
A19: 20/6/24 | C19: IBFT | E19: 50000 | G19: =G18-E19+F19 -> 6877
A20: 22/6/24 | B20: G206 | C20: 1.5L-Caps,30mm caps,1.5L shoper | F20: 13820 | G20: =G19-E20+F20 -> 20697
A21: 25/6/24 | B21: G237 | C21: 30mm caps,30mm seal, jumbo PPF, PPF 10" | F21: 9600 | G21: =G20-E21+F21 -> 30297
A22: 26/6/24 | C22: IBFT | E22: 20000 | G22: =G21-E22+F22 -> 10297
A23: 29/6/24 | B23: G271 | C23: 30mm caps, 30mm seal | F23: 6200 | G23: =G22-E23+F23 -> 16497
A24: 45298 | B24: G290 | C24: 1.5L-Caps,30mm seal,1.5L shoper,500ml-caps,500ml shoper | F24: 25477 | G24: =G23-E24+F24 -> 41974
A25: 45329 | B25: G313 | C25: 19L caps,1.5L- caps,500ml- caps | F25: 9570 | G25: =G24-E25+F25 -> 51544
A26: 45358 | B26: G326 | C26: 30mmcaps,30mm seal, 1.5L shoper,500ml shoper | F26: 7300 | G26: =G25-E26+F26 -> 58844
A27: 45419 | C27: IBFT | E27: 30000 | G27: =G26-E27+F27 -> 28844
A28: 45542 | B28: G396 | C28: 19L Caps | F28: 1100 | G28: =G27-E28+F28 -> 29944
A29: 18/7/24 | B29: G450 | C29: 500ml-Caps,500ml shoper,30mm caps | F29: 25900 | G29: =G28-E29+F29 -> 55844
A30: 15/7/24 | C30: IBFT | E30: 29900 | G30: =G29-E30+F30 -> 25944
A31: 45391 | B31: G643 | C31: 1.5L E, 500L, Shoper | F31: 625 | G31: =G30-E31+F31 -> 26569
A32: 45361 | B32: G1137 | C32: Remaining Amount | F32: 590 | G32: =G31-E32+F32 -> 27159
A33: 23/10/2024 | B33: G1307 | C33: Remaining Amount | F33: 630 | G33: =G32-E33+F33 -> 27789
A34: 29/10/24 | B34: G1358 | C34: 500ml - Caps, 500ml Shoper, 30mm Caps | F34: 5230 | G34: =G33-E34+F34 -> 33019
A35: 31/10/24 | C35: Amount Cancelled from IBFT | F35: 7950 | G35: =G34-E35+F35 -> 40969
A36: 45362 | B36: G1408 | C36: 500ml E | F36: 3225 | G36: =G35-E36+F36 -> 44194
A37: 45333 | B37: G1399 | C37: Remaining Amount | D37: IBFT received 10900 total amount is 11650 | F37: 750 | G37: =G36-E37+F37 -> 44944
A38: 45393 | B38: G1428 | C38: Remaining Amount | D38: Total amount Bill G1428 39200 from which 20000 IBFT | F38: 19200 | G38: =G37-E38+F38 -> 64144
A39: 45546 | B39: G1460 | C39: 1.5L - Caps | F39: 5390 | G39: =G38-E39+F39 -> 69534
A40: 45423 | B40: Exp Sheet | C40: Cash Deposit | E40: 19500 | G40: =G39-E40+F40 -> 50034
A41: 19/10/24 | B41: Exp Sheet | C41: Cash Deposit | E41: 4830 | G41: =G40-E41+F41 -> 45204
...

Sheet Al Bayan Water 
A1: LEDGER
A3: Account Holder's Name | D3: Al Bayan Water
A4: Pg # | C4: New Reg(70)
A5: Date | B5: Ref No. | C5: Description | D5: Debit | E5: Credit | F5: Balance
A6: 44599 | C6: Old Balnace | E6: 161205 | F6: =E6-D6 -> 161205
F7: =E7-D7 -> 0
A8: GRAND TOTAL | F8: =F7-D8+E8 -> 0

Sheet Aqua Need
A1: LEDGER
A3: Account Holder's Name | D3: Aqua Need
A4: Pg # | C4: New Reg (186)
A5: Date | B5: Ref No. | C5: Description | D5: Debit | E5: Credit | F5: Balance
A6: 45749 | B6: H426 | C6: Remaining Amount | E6: 4000 | F6: =E6-D6 -> 4000
A7: 45810 | B7: H448 | C7: Remaining Amount | E7: 12250 | F7: =E7-D7+F6 -> 16250
A8: 45810 | B8: H446 | C8: 1.5L-Caps, 500ml- Caps, 6L + Caps | E8: 19600 | F8: =E8-D8+F7 -> 35850
A9: 45810 | B9: H447 | C9: Remaining Amount | E9: 5340 | F9: =E9-D9+F8 -> 41190
A10: 45871 | B10: H460 | C10: 1.5L-Caps, 500ml- Caps, 6L + Caps | E10: 12140 | F10: =E10-D10+F9 -> 53330
A11: 45871 | B11: Exp Sh | C11: Cash deposit | D11: 5880 | F11: =E11-D11+F10 -> 47450
A12: 45871 | B12: Exp Sh | C12: Cash deposit | D12: 31300 | F12: =E12-D12+F11 -> 16150
A13: 45779 | B13: H434 | C13: Old Balance Received | D13: 4000 | F13: =E13-D13+F12 -> 12150
A14: 45902 | B14: Exp Sh | C14: Cash deposit | D14: 12150 | F14: =E14-D14+F13 -> 0
A15: 45932 | B15: H472 | C15: 1.5L -Caps, 500ml - Caps | E15: 17972 | F15: =E15-D15+F14 -> 17972
A16: 45963 | B16: H488 | C16: 1.5L- Caps, 500ml - caps, 6L+ Caps | E16: 25420 | F16: =E16-D16+F15 -> 43392
A17: 45963 | B17: Exp Sh | C17: Cash deposit | D17: 17500 | F17: =E17-D17+F16 -> 25892
A18: 45993 | C18: IBFT 50,000 deposited remaining amount deposit for plant | D18: 50000 | F18: =E18-D18+F17 -> -24108
A19: 45993 | B19: H504 | C19: 1.5L-Caps, 500ml- Caps, 6L + Caps | E19: 17250 | F19: =E19-D19+F18 -> -6858
A20: 13/2/25 | B20: H524 | C20: 1.5L-Caps, 500ml- Caps | E20: 15120 | F20: =E20-D20+F19 -> 8262
A21: 16/2/25 | B21: H547 | C21: 30mm Seal | E21: 1800 | F21: =E21-D21+F20 -> 10062
A22: 16/2/25 | B22: H544 | C22: Remaining Amount | E22: 4600 | F22: =E22-D22+F21 -> 14662
A23: 18/2/25 | B23: Exp Sh | C23: Cash deposit | D23: 6400 | F23: =E23-D23+F22 -> 8262
A24: 20/2/25 | B24: H593 | C24: 1.5L-Caps, 500ml-Caps,500ml Seal | E24: 23050 | F24: =E24-D24+F23 -> 31312
A25: 19/2/25 | B25: H586 | C25: 1.5L-Caps, | E25: 1540 | F25: =E25-D25+F24 -> 32852
A26: 25/2/25 | B26: Exp Sh | C26: Cash deposit | D26: 1800 | F26: =E26-D26+F25 -> 31052
A27: 25/2/25 | B27: Exp Sh | C27: Cash deposit | D27: 18790 | F27: =E27-D27+F26 -> 12262
A28: 25/2/25 | B28: H644 | C28: Remaining Amount | E28: 10000 | F28: =E28-D28+F27 -> 22262
A29: 26/2/25 | B29: H660 | C29: 6L+ Caps, 1.5L-Caps | E29: 5140 | F29: =E29-D29+F28 -> 27402
A30: 27/2/25 | B30: H667 | C30: Remaining Amount | E30: 9880 | F30: =E30-D30+F29 -> 37282
A31: 45691 | B31: H693 | C31: Remaining Amount | E31: 7500 | F31: =E31-D31+F30 -> 44782
A32: 45780 | C32: Cash deposit | D32: 20000 | F32: =E32-D32+F31 -> 24782
A33: 45780 | B33: H728 | C33: 1.5L-Caps, 500ml -Caps | E33: 8340 | F33: =E33-D33+F32 -> 33122
A34: 45811 | B34: H736 | C34: 1.5L-Caps, 500ml-Caps, Ca, Na | E34: 3500 | F34: =E34-D34+F33 -> 36622
A35: 45872 | B35: H741 | C35: Remaining Amount | E35: 12380 | F35: =E35-D35+F34 -> 49002
A36: 45933 | B36: H768 | C36: Remaining Amount | E36: 15000 | F36: =E36-D36+F35 -> 64002
A37: 45994 | B37: H789 | C37: Remaining Amount | E37: 23530 | F37: =E37-D37+F36 -> 87532
A38: 16/3/25 | B38: H830 | C38: Remaining Amount | E38: 7490 | F38: =E38-D38+F37 -> 95022
A39: 16/3/25 | B39: H832 | C39: 30mm Caps | E39: 4200 | F39: =E39-D39+F38 -> 99222
A40: 18/3/25 | B40: H858 | C40: 1.5L-Caps, 500ml-Caps, 1.5L Shoper, 500ml Shoper | E40: 19260 | F40: =E40-D40+F39 -> 118482
A41: 19/3/25 | B41: Exp Sh | C41: Cash deposit | D41: 25000 | F41: =E41-D41+F40 -> 93482
...

Sheet Ab e Rose Water
A1: LEDGER
A3: Account Holder's Name | D3: Ab e Rose Water
A4: Pg # | C4: Old Reg(178)
A5: Date | B5: Ref No. | C5: Description | D5: Debit | E5: Credit | F5: Balance
A6: 44599 | C6: Old Balnace | E6: 27468 | F6: =E6-D6 -> 27468
F7: =F6-D7+E7 -> 27468
A8: GRAND TOTAL | F8: =F7-D8+E8 -> 27468

Sheet Aqua Musafi
A1: LEDGER
A3: Account Holder's Name | D3: Aqua Musafi
A4: Pg # | C4: New Reg (141)
A5: Date | B5: Ref No. | C5: Description | D5: Debit | E5: Credit | F5: Balance
C6: Old Balance | E6: 41490 | F6: =E6-D6 -> 41490
A7: 24/01/24 | B7: Exp Sh | C7: Cash Deposit | D7: 500 | F7: =F6-D7+E7 -> 40990
A8: 45445 | B8: Exp Sh | C8: Cash Deposit | D8: 500 | F8: =F7-D8+E8 -> 40490
A9: 14/02/24 | B9: F739 | C9: 1.5L Bottle | E9: 400 | F9: =F8-D9+E9 -> 40890
A10: 14/02/24 | B10: F742 | C10: 1.5L Bottle,.. | E10: 240 | F10: =F9-D10+E10 -> 41130
A11: 15/02/24 | B11: F759 | C11: Cash Deposit | D11: 680 | F11: =F10-D11+E11 -> 40450
A12: 19/02/24 | B12: F794 | C12: 6L Bottle | E12: 1200 | F12: =F11-D12+E12 -> 41650
A13: 13/06/24 | B13: G149 | C13: 1.5 L Bottle,.. | E13: 150 | F13: =F12-D13+E13 -> 41800
A14: 13/06/24 | B14: Exp Sh | C14: Cash Deposit | D14: 2000 | F14: =F13-D14+E14 -> 39800
A15: 45602 | B15: G149 | C15: 500 ml Bottle,.. | E15: 2000 | F15: =F14-D15+E15 -> 41800
A16: 27/7/24 | B16: G529 | C16: 1.5L + caps, 500ml + caps,.. | E16: 519 | F16: =F15-D16+E16 -> 42319
A17: 45299 | B17: G580 | C17: 5L+ caps, 500ml - caps, 1.5L-caps,… | E17: 469 | F17: =F16-D17+E17 -> 42788
A18: 45542 | C18: IBFT | D18: 2700 | F18: =F17-D18+E18 -> 40088
A19: 45299 | B19: Exp Sh | C19: Cash Deposit | D19: 510 | F19: =F18-D19+E19 -> 39578
C20: 19L Used Bottle Purchase | D20: 9000 | F20: =F19-D20+E20 -> 30578
F21: =F20-D21+E21 -> 30578
F22: =F21-D22+E22 -> 30578
F23: =F22-D23+E23 -> 30578
F24: =F23-D24+E24 -> 30578
A25: GRAND TOTAL | F25: =F24-D25+E25 -> 30578

Sheet Al Javed Ice Factory
A1: LEDGER
A3: Account Holder's Name | D3: Al Javed Ice Factory
A4: Pg # | C4: New Reg(147)
A5: Date | B5: Ref No. | C5: Description | D5: Debit | E5: Credit | F5: Balance
A6: 15/08/23 | C6: Old Balnace | E6: 17200 | F6: =E6-D6 -> 17200
A7: 45326 | B7: F1247 | C7: Sand,Jambo PPf,.. | E7: 8500 | F7: =F6-D7+E7 -> 25700
A8: 45296 | B8: F1592 | C8: PPF 10",. | E8: 850 | F8: =F7-D8+E8 -> 26550
F9: =F8-D9+E9 -> 26550
A10: GRAND TOTAL | F10: =F9-D10+E10 -> 26550

Sheet Al Maida Water
A1: LEDGER
A3: Account Holder's Name | D3: Al Maida Water
A4: Pg # | C4: New Reg(156)
A5: Date | B5: Ref No. | C5: Description | D5: Debit | E5: Credit | F5: Balance
A6: 45383 | C6: Old Balnace | E6: 9560 | F6: =E6-D6 -> 9560
A7: 45414 | C7: IBFT | D7: 9560 | F7: =F6-D7+E7 -> 0
A8: 17/02/24 | B8: F770 | C8: 19L Bottle | E8: 13000 | F8: =F7-D8+E8 -> 13000
A9: 45386 | B9: Exp Sh | C9: 36 Leak Bottle @85/- | D9: 3060 | F9: =F8-D9+E9 -> 9940
A10: 18/04/24 | B10: F1436 | C10: 19L Bottle | E10: 13000 | F10: =F9-D10+E10 -> 22940
A11: 18/04/24 | C11: IBFT | D11: 20000 | F11: =F10-D11+E11 -> 2940
A12: 28/05/24 | B12: F1939 | C12: 19L Bottle | E12: 28000 | F12: =F11-D12+E12 -> 30940
A13: 45812 | B13: H1039 | C13: Extra amount received through IBFT | D13: 500 | F13: =F12-D13+E13 -> 30440
A14: 31/12/25 | B14: j600 | C14: 19lbrush...... | E14: 5112 | F14: =F13-D14+E14 -> 35552
F15: =F14-D15+E15 -> 35552
F16: =F15-D16+E16 -> 35552
F17: =F16-D17+E17 -> 35552
F18: =F17-D18+E18 -> 35552
F19: =F18-D19+E19 -> 35552
F20: =F19-D20+E20 -> 35552
F21: =F20-D21+E21 -> 35552
F22: =F21-D22+E22 -> 35552
F23: =F22-D23+E23 -> 35552
A24: GRAND TOTAL | F24: =F23-D24+E24 -> 35552

Sheet Ahmed N One water
A1: LEDGER
A3: Account Holder's Name | D3: Ahmed N One water
A4: Pg # | C4: New Reg(124)
A5: Date | B5: Ref No. | C5: Description | D5: Debit | E5: Credit | F5: Balance
A6: 23/01/24 | C6: Old Balance | E6: 85000 | F6: =E6-D6 -> 85000
A7: 23/01/24 | B7: F542 | C7: Cash Deposit | D7: 160 | F7: =F6-D7+E7 -> 84840
A8: 27/01/24 | B8: F566 | C8: 6L Bottle,.. | E8: 2000 | F8: =F7-D8+E8 -> 86840
A9: 30/01/24 | B9: F593 | C9: 1.5L Bottle,.. | E9: 1450 | F9: =F8-D9+E9 -> 88290
A10: 45293 | B10: F608 | C10: 1.5L Bottle,.. | E10: 12000 | F10: =F9-D10+E10 -> 100290
A11: 45353 | B11: F626 | C11: 1.5L Bottle,.. | E11: 20770 | F11: =F10-D11+E11 -> 121060
A12: 45414 | B12: F655 | C12: 1.5L Bottle,.. | E12: 13850 | F12: =F11-D12+E12 -> 134910
A13: 45475 | B13: F677 | C13: 1.5L Bottle,.. | E13: 33000 | F13: =F12-D13+E13 -> 167910
A14: 45567 | B14: F694 | C14: 1.5L Bottle,.. | E14: 16680 | F14: =F13-D14+E14 -> 184590
A15: 45628 | B15: F719 | C15: 1.5L Bottle,.. | E15: 12480 | F15: =F14-D15+E15 -> 197070
A16: 14/2/24 | B16: F749 | C16: 1.5L Bottle,.. | E16: 3550 | F16: =F15-D16+E16 -> 200620
A17: 18/02/4 | B17: F778 | C17: 1.5L Bottle,.. | E17: 820 | F17: =F16-D17+E17 -> 201440
A18: 18/02/24 | B18: F784 | C18: 19L Bottle | E18: 1350 | F18: =F17-D18+E18 -> 202790
A19: 17/02/24 | B19: F767 | C19: 6L Bottle,.. | E19: 410 | F19: =F18-D19+E19 -> 203200
A20: 21/02/24 | B20: F820 | C20: 1.5L Shoper | E20: 100 | F20: =F19-D20+E20 -> 203300
A21: 24/02/24 | B21: F845 | C21: 1.5L Bottle,.. | E21: 50 | F21: =F20-D21+E21 -> 203350
C22: Loader Rickshaw | E22: 50000 | F22: =F21-D22+E22 -> 253350
A23: 27/02/24 | B23: F888 | C23: Calculation Mistake | D23: 1660 | F23: =F22-D23+E23 -> 251690
A24: 45325 | B24: F934 | C24: 1.5L Bottle,.. | E24: 14550 | F24: =F23-D24+E24 -> 266240
A25: 45385 | B25: F952 | C25: 1.5L Bottle,.. | E25: 9620 | F25: =F24-D25+E25 -> 275860
A26: 45446 | B26: F976 | C26: 1.5L Bottle,.. | E26: 14550 | F26: =F25-D26+E26 -> 290410
A27: 45476 | B27: F1005 | C27: 1.5L Bottle,.. | E27: 12010 | F27: =F26-D27+E27 -> 302420
A28: 45568 | B28: F1017 | C28: 1.5L Bottle,.. | E28: 19830 | F28: =F27-D28+E28 -> 322250
A29: 16/03/24 | B29: F1082 | C29: 1.5L Bottle,.. | E29: 21980 | F29: =F28-D29+E29 -> 344230
A30: 26/03/24 | B30: F1178 | C30: 19L Bottle,.. | E30: 34000 | F30: =F29-D30+E30 -> 378230
A31: 45295 | B31: F1231 | C31: 1.5L Bottle,.. | E31: 14160 | F31: =F30-D31+E31 -> 392390
A32: 04/04/024 | B32: F1273 | C32: 1.5L Bottle,.. | E32: 13250 | F32: =F31-D32+E32 -> 405640
A33: 45477 | B33: F1305 | C33: 1.5L Bottle,.. | E33: 10870 | F33: =F32-D33+E33 -> 416510
A34: 45508 | B34: F1317 | C34: 1.5L Bottle,.. | E34: 15390 | F34: =F33-D34+E34 -> 431900
A35: 13/04/24 | B35: F1338 | C35: 1.5L Bottle,.. | E35: 28620 | F35: =F34-D35+E35 -> 460520
A36: 14/04/24 | B36: F1359 | C36: 1.5L Bottle,.. | E36: 20220 | F36: =F35-D36+E36 -> 480740
A37: 18/04/24 | B37: F1430 | C37: 500 ml Bottle | E37: 400 | F37: =F36-D37+E37 -> 481140
A38: 21/04/24 | B38: F1463 | C38: 1.5L Bottle,.. | E38: 16450 | F38: =F37-D38+E38 -> 497590
A39: 22/04/24 | B39: Exp Sh | C39: Cash Deposit | D39: 12000 | F39: =F38-D39+E39 -> 485590
A40: 45296 | B40: F1597 | C40: 1.5L Shoper,. | E40: 28790 | F40: =F39-D40+E40 -> 514380
A41: 45387 | B41: F1626 | C41: 1.5L Bottle,.. | E41: 38100 | F41: =F40-D41+E41 -> 552480
...

Sheet Al Shafi Water (Younas sb)
A1: LEDGER
A3: Account Holder's Name | D3: Al Shafi Water (Younas sb)
A4: Pg # | C4: New Reg(110)
A5: Date | B5: Ref No. | C5: Description | D5: Debit | E5: Credit | F5: Balance
A6: 23/08/23 | B6: E905 | C6: 19L Bottle,.. | E6: 4350 | F6: =E6-D6 -> 4350
A7: 26/08/23 | B7: E953 | C7: Flim Tech Memb,.. | E7: 60500 | F7: =F6-D7+E7 -> 64850
C8: Loader Rickshaw | D8: 40000 | F8: =F7-D8+E8 -> 24850
A9: 45328 | B9: G12 | C9: 19L Bottle | E9: 400 | F9: =F8-D9+E9 -> 25250
A10: 14/7/24 | B10: G426 | D10: 1900 | F10: =F9-D10+E10 -> 23350
A11: 23/3/25 | B11: H902 | C11: Amount Received by CCard=100,000 Cash they received =35000, Tax deducted=1800 (1.8%) | D11: 63200 | F11: =F10-D11+E11 -> -39850
A12: 23/3/25 | B12: H902 | C12: 19L Bottle | E12: 42000 | F12: =F11-D12+E12 -> 2150
F13: =F12-D13+E13 -> 2150
F14: =F13-D14+E14 -> 2150
F15: =F14-D15+E15 -> 2150
F16: =F15-D16+E16 -> 2150
F17: =F16-D17+E17 -> 2150
F18: =F17-D18+E18 -> 2150
F19: =F18-D19+E19 -> 2150
A20: GRAND TOTAL | F20: =F19-D20+E20 -> 2150

Sheet Al Khidmat lodhran 
A1: LEDGER
A3: Account Holder's Name | D3: Al Khidmat lodhran
A4: Pg # | C4: Old reg(76)
A5: Date | B5: Ref No. | C5: Description | D5: Debit | E5: Credit | F5: Balance
A6: 18/01/24 | C6: Old Balnace | E6: 71024 | F6: =E6-D6 -> 71024
A7: 15/12/2024 | B7: Exp sh | C7: Installment of plant | D7: 10000 | F7: =F6-D7+E7 -> 61024
C8: total payment nill in haf ton plant
A9: 45608 | B9: Exp sh | C9: Installment of plant | D9: 10000 | F9: =F7-D9+E9 -> 51024
A10: GRAND TOTAL | F10: =F9-D10+E10 -> 51024

Sheet Al Khidmat Bwp
A1: LEDGER
A3: Account Holder's Name | D3: Al Khidmat Bwp
A4: Pg # | C4: New Reg (23)
A5: Date | B5: Ref No. | C5: Description | D5: Debit | E5: Credit | F5: Balance
C6: Old Balance | E6: 27105 | F6: =E6-D6 -> 27105
A7: 45415 | B7: F966 | C7: Jambo PPf,.. | E7: 1950 | F7: =F6+E7-D7 -> 29055
A8: 45326 | B8: Exp Sh | C8: Net Cash Dep | D8: 6750 | F8: =F7+E8-D8 -> 22305
A9: 45326 | B9: Exp Sh | C9: Cheque | D9: 11340 | F9: =F8+E9-D9 -> 10965
A10: 45387 | B10: F1625 | C10: 1.5L Bottle,.. | E10: 2000 | F10: =F9+E10-D10 -> 12965
A11: 14/05/24 | B11: Exp Sh | C11: Net Cash Dep | D11: 2000 | F11: =F10+E11-D11 -> 10965
A12: 45329 | B12: G304 | C12: TDS meter claim | E12: 500 | F12: =F11+E12-D12 -> 11465
C13: cash deposit | D13: 500 | F13: =F12+E13-D13 -> 10965
A14: 17/4/25 | B14: Exp Sh | C14: cash deposit | F14: =F13+E14-D14 -> 10965
A15: 25/5/25 | B15: H1778 | C15: 19L Caps | E15: 500 | F15: =F14+E15-D15 -> 11465
A16: 45694 | D16: 500 | F16: =F15+E16-D16 -> 10965
A17: 19/6/25 | B17: I 35 | C17: 30mm Seal | E17: 170 | F17: =F16+E17-D17 -> 11135
A18: 30/6/25 | B18: I 164 | C18: Plant Maintance | E18: 31500 | F18: =F17+E18-D18 -> 42635
A19: 22/7/25 | B19: Exp Sh | C19: Cash deposit | D19: 500 | F19: =F18+E19-D19 -> 42135
A20: 45878 | B20: I 1089 | C20: 500ml+caps…. | E20: 31800 | F20: =F19+E20-D20 -> 73935
A21: 28/9/2025 | B21: I 1423 | E21: 2950 | F21: =F20+E21-D21 -> 76885
A22: 45911 | B22: j7 | C22: flunch+membrane bush | E22: 3060 | F22: =F21+E22-D22 -> 79945
A23: GRAND TOTAL | F23: =F22+E23-D23 -> 79945

Sheet Abshar Water
A1: LEDGER
A3: Account Holder's Name | D3: Abshar Water
A4: Pg # | C4: New Reg(58)
A5: Date | B5: Ref No. | C5: Description | D5: Debit | E5: Credit | F5: Balance
A6: 45116 | B6: E1103 | C6: 1.5L Bottle with Caps | E6: 5450 | F6: =E6-D6 -> 5450
C7: Plant Remaing Amount | E7: 10000 | F7: =F6-D7+E7 -> 15450
F8: =F7-D8+E8 -> 15450
F9: =F8-D9+E9 -> 15450
F10: =F9-D10+E10 -> 15450
F11: =F10-D11+E11 -> 15450
A12: GRAND TOTAL | F12: =F11-D12+E12 -> 15450

Sheet Aqua Marine 
A1: LEDGER
A3: Account Holder's Name | D3: Aqua Marine
A4: Pg # | C4: New Reg(150)
A5: Date | B5: Ref No. | C5: Description | D5: Debit | E5: Credit | F5: Balance
A6: 45268 | C6: Opening Balnace | E6: 73127 | F6: =E6-D6 -> 73127 | H6: `
A7: 45414 | B7: F652 | C7: 1.5L Shoper,.. | E7: 6500 | F7: =F6-D7+E7 -> 79627
A8: 45538 | B8: F1010 | C8: Cash Dep | D8: 6500 | F8: =F7-D8+E8 -> 73127
F9: =F8-D9+E9 -> 73127
A10: GRAND TOTAL | F10: =F9-D10+E10 -> 73127

Sheet Ab e Hayat Plus
A1: LEDGER
A3: Account Holder's Name | D3: Ab e Hayat Plus
A4: Pg # | C4: New reg(27)
A5: Date | B5: Ref No. | C5: Description | D5: Debit | E5: Credit | F5: Balance
C6: Old Balnace | E6: 15763 | F6: =E6-D6 -> 15763
A7: 18/10/24 | C7: Add 20 L Can | D7: 23500 | F7: =F6-D7+E7 -> -7737
C8: add , Diff | D8: 1000 | F8: =F7-D8+E8 -> -8737
C9: Add | D9: 710 | F9: =F8-D9+E9 -> -9447
C10: Bill Diff | D10: 300 | F10: =F9-D10+E10 -> -9747
A11: 14/04/24 | B11: F1355 | C11: 500 ml Bottle | E11: 10000 | F11: =F10-D11+E11 -> 253
F12: =F11-D12+E12 -> 253
F13: =F12-D13+E13 -> 253
F14: =F13-D14+E14 -> 253
F15: =F14-D15+E15 -> 253
A16: GRAND TOTAL | F16: =F15-D16+E16 -> 253

Sheet Ajwah Water
A1: LEDGER
A3: Account Holder's Name | D3: Ajwah Water
A4: Pg #
A5: Date | B5: Ref No. | C5: Description | D5: Debit | E5: Credit | F5: Balance
A6: 29/4/25 | B6: 1565 | C6: Jumbo PPFGold, H.P Pump repairing,…Oold balance 3000, bill amount 22400, deposited 10,000 | E6: 12400 | F6: =E6-D6 -> 12400
A7: 19/10/25 | B7: I 1703 | C7: Jumbo PPF | E7: 2400 | F7: =F6-D7+E7 -> 14800
F8: =F7-D8+E8 -> 14800
A9: GRAND TOTAL | F9: =F8-D9+E9 -> 14800

Sheet Aqsa Water
A1: LEDGER
A3: Account Holder's Name | D3: Aqsa Water
A4: Pg # | C4: Old Reg(179)
A5: Date | B5: Ref No. | C5: Description | D5: Debit | E5: Credit | F5: Balance
A6: 18/10/21 | C6: Old Balnace | E6: 41181 | F6: =E6-D6 -> 41181
C7: Payment Rcv /cheq ky badly | E7: 10000 | F7: =F6-D7+E7 -> 51181
F8: =F7-D8+E8 -> 51181
A9: GRAND TOTAL | F9: =F8-D9+E9 -> 51181

Sheet Al Azam Water
A1: LEDGER
A3: Account Holder's Name | D3: Al Azam Water
A4: Pg # | C4: New Reg(165)
A5: Date | B5: Ref No. | C5: Description | D5: Debit | E5: Credit | F5: Balance
A6: 20/11/23 | C6: Old Balnace | E6: 42100 | F6: =E6-D6 -> 42100
A7: 28/11/23 | B7: F35 | C7: Ca, Mg, Na, | E7: 1100 | F7: =F6-D7+E7 -> 43200
A8: 29/01/24 | B8: F580 | C8: Antiscaler | E8: 2200 | F8: =F7-D8+E8 -> 45400
A9: 15/02/24 | C9: 1.5L Bottle ,Q=11200 | E9: 117600 | F9: =F8-D9+E9 -> 163000
A10: 15/02/24 | C10: 0.5L Bottle,Q=8500 | E10: 54400 | F10: =F9-D10+E10 -> 217400
A11: 15/02/24 | C11: IBFT | D11: 135000 | F11: =F10-D11+E11 -> 82400
A12: 20/02/24 | C12: IBFT | D12: 40000 | F12: =F11-D12+E12 -> 42400
A13: 45568 | B13: F1025 | C13: 30 mm Caps,.. | E13: 28040 | F13: =F12-D13+E13 -> 70440
A14: 23/03/24 | B14: F1141 | C14: Less price witten in bill #F1141 | E14: 510 | F14: =F13-D14+E14 -> 70950
A15: 28/04/24 | C15: Discount | D15: 2450 | F15: =F14-D15+E15 -> 68500
A16: 28/04/24 | C16: Net Cash in Hand | D16: 50000 | F16: =F15-D16+E16 -> 18500
A17: 28/04/24 | C17: wall socket1 1/2",.. | E17: 42160 | F17: =F16-D17+E17 -> 60660
C18: Return Feed Pump in Bill #F1558 | D18: 35000 | F18: =F17-D18+E18 -> 25660
A19: 24/7/24 | C19: Cash Deposit | D19: 20000 | F19: =F18-D19+E19 -> 5660
A20: 15/9/24 | B20: G840 | C20: 500ml - caps, 30mm caps, 500ml Shoper | E20: 40125 | F20: =F19-D20+E20 -> 45785
A21: 45839 | B21: H58 | C21: Remaining Amount from 1875 after paying 1500 | E21: 375 | F21: =F20-D21+E21 -> 46160
C22: Remaining Amount of RO Plant (Haji) | E22: 70000 | F22: =F21-D22+E22 -> 116160
A23: 26/3/25 | B23: H935 | C23: Jumbo PPY 10 | E23: 1500 | F23: =F22-D23+E23 -> 117660
C24: Cash Deposit | D24: 70000 | F24: =F23-D24+E24 -> 47660
A25: 45845 | B25: I 255 | C25: Jumbo PPF, Antiscalar, Ball Valve1", Sodium, Mg | E25: 51030 | F25: =F24-D25+E25 -> 98690
A26: 45816 | B26: I 641 | C26: 1.5LShoper | D26: 2750 | F26: =F25-D26+E26 -> 95940
F27: =F26-D27+E27 -> 95940
F28: =F27-D28+E28 -> 95940
F29: =F28-D29+E29 -> 95940
A30: GRAND TOTAL | F30: =F29-D30+E30 -> 95940

Sheet Aqua Santa
A1: LEDGER
A3: Account Holder's Name | D3: Aqua Santa & Dolce
A4: Pg # | C4: Old Reg(180)
A5: Date | B5: Ref No. | C5: Description | D5: Debit | E5: Credit | F5: Balance
A6: 23/05/3 | C6: Old Balnace | E6: 9684 | F6: =E6-D6 -> 9684
F7: =F6-D7+E7 -> 9684
A8: GRAND TOTAL | F8: =F7-D8+E8 -> 9684

Sheet Ahmed Ice Factory 
A1: LEDGER
A3: Account Holder's Name | D3: Ahmed Ice Factory (LD)
A4: Pg # | C4: Old Reg(182)
A5: Date | B5: Ref No. | C5: Description | D5: Debit | E5: Credit | F5: Balance
A6: 15/07/3 | C6: Old Balnace | E6: 274413 | F6: =E6-D6 -> 274413
A7: 15/7/23 | B7: E404 | C7: IBFT | D7: 50000 | F7: =F6-D7+E7 -> 224413
A8: 24/7/23 | B8: Exp Sh | C8: Cash Deposit | D8: 50000 | F8: =F7-D8+E8 -> 174413
A9: 45602 | B9: Purchase | C9: Memb Shell & Feed Pump | D9: 50000 | F9: =F8-D9+E9 -> 124413
A10: 30/7/24 | B10: Pump Difference | E10: 5000 | F10: =F9-D10+E10 -> 129413
A11: 30/7/24 | B11: IBFT | D11: 64500 | F11: =F10-D11+E11 -> 64913
A12: 45330 | B12: IBFT | D12: 40000 | F12: =F11-D12+E12 -> 24913
B13: Cash Deposit | D13: 24913 | F13: =F12-D13+E13 -> 0
A14: 45482 | C14: Fittings High Pressure Pump Online TDS Meter | E14: 160204 | F14: =F13-D14+E14 -> 160204
A15: 45512 | C15: Cash Deposit | D15: 8000 | F15: =F14-D15+E15 -> 152204
A16: 45512 | C16: Cash Deposit | D16: 50000 | F16: =F15-D16+E16 -> 102204
A17: 45512 | C17: 4 Sand Bags | E17: 4000 | F17: =F16-D17+E17 -> 106204
A18: 17/4/25 | B18: H1217 | C18: Jumbo PPF | D18: 1500 | F18: =F17-D18+E18 -> 104704
A19: 17/4/25 | B19: H1239 | C19: Elbow , Union, Plane socket,… | E19: 5460 | F19: =F18-D19+E19 -> 110164
A20: 22/4/25 | C20: IBFT | D20: 10000 | F20: =F19-D20+E20 -> 100164
A21: 22/4/25 | B21: H1302 | C21: wall socket 1", F socket1", Mem washing chemical | E21: 6350 | F21: =F20-D21+E21 -> 106514
F22: =F21-D22+E22 -> 106514
F23: =F22-D23+E23 -> 106514
F24: =F23-D24+E24 -> 106514
F25: =F24-D25+E25 -> 106514
F26: =F25-D26+E26 -> 106514
A27: GRAND TOTAL | F27: =F26-D27+E27 -> 106514

Sheet Aqua Shereen 
A1: LEDGER
A3: Account Holder's Name | D3: Aqua Shereen
A4: Pg # | C4: Old Reg(73)
A5: Date | B5: Ref No. | C5: Description | D5: Debit | E5: Credit | F5: Balance
A6: 29/3/23 | C6: Old Balnace | E6: 54965 | F6: =E6-D6 -> 54965
F7: =F6-D7+E7 -> 54965
A8: GRAND TOTAL | F8: =F7-D8+E8 -> 54965

Sheet Alien Water( Bwp)
A1: LEDGER
A3: Account Holder's Name | D3: Alien Water( Bwp)
A4: Pg # | C4: Old Reg (122)
A5: Date | B5: Ref No. | C5: Description | D5: Debit | E5: Credit | F5: Balance
C6: Opening Balnace | F6: =E6-D6 -> 0
F7: =F6-D7+E7 -> 0
F8: =F7-D8+E8 -> 0
F9: =F8-D9+E9 -> 0
A10: GRAND TOTAL | F10: =F9-D10+E10 -> 0

Sheet Al Safina Water
A1: LEDGER
A3: Account Holder's Name | D3: Al Safina Water
A4: Pg #
A5: Date | B5: Ref No. | C5: Description | D5: Debit | E5: Credit | F5: Balance
C6: Opening Balnace | F6: =E6-D6 -> 0
F7: =F6-D7+E7 -> 0
F8: =F7-D8+E8 -> 0
F9: =F8-D9+E9 -> 0
F10: =F9-D10+E10 -> 0
F11: =F10-D11+E11 -> 0
F12: =F11-D12+E12 -> 0
F13: =F12-D13+E13 -> 0
F14: =F13-D14+E14 -> 0
F15: =F14-D15+E15 -> 0
F16: =F15-D16+E16 -> 0
F17: =F16-D17+E17 -> 0
F18: =F17-D18+E18 -> 0
... F100: =F99-D100+E100 -> 0
A101: GRAND TOTAL | F101: =F100-D101+E101 -> 0

Sheet Alien Water( Lodhran)
A1: LEDGER
A3: Account Holder's Name | D3: Alien Water( Lodhran)
A4: Pg # | C4: Old reg(127)
A5: Date | B5: Ref No. | C5: Description | D5: Debit | E5: Credit | F5: Balance
A6: 21/04/24 | B6: F1453 | C6: Flim tech R.O Memb | E6: 52100 | F6: =E6-D6 -> 52100
A7: 45540 | C7: E.P | D7: 10000 | F7: =F6-D7+E7 -> 42100
A8: 14/9/24 | C8: cash deposit | D8: 10000 | F8: =F7-D8+E8 -> 32100
A9: 16/7/24 | C9: cash deposit | D9: 10000 | F9: =F8-D9+E9 -> 22100
A10: 13/4/25 | B10: H1133 | C10: Mem Shell Seal (2) | E10: 9700 | F10: =F9-D10+E10 -> 31800
A11: 13/4/25 | C11: IBFT | D11: 20000 | F11: =F10-D11+E11 -> 11800
F12: =F11-D12+E12 -> 11800
F13: =F12-D13+E13 -> 11800
A14: GRAND TOTAL | F14: =F13-D14+E14 -> 11800

Sheet Al Nemat Water
A1: LEDGER
A3: Account Holder's Name | D3: Al Nemat Water
A4: Pg #
A5: Date | B5: Ref No. | C5: Description | D5: Debit | E5: Credit | F5: Balance
C6: Opening Balnace | F6: =E6-D6 -> 0
F7: =F6-D7+E7 -> 0
F8: =F7-D8+E8 -> 0
F9: =F8-D9+E9 -> 0
F10: =F9-D10+E10 -> 0
A11: GRAND TOTAL | F11: =F10-D11+E11 -> 0

Sheet A.F Water
A1: LEDGER
A3: Account Holder's Name | D3: A.F Water
A4: Pg # | C4: Old Reg(172)
A5: Date | B5: Ref No. | C5: Description | D5: Debit | E5: Credit | F5: Balance
A6: 20/7/22 | C6: Old Balnace | E6: 10351 | F6: =E6-D6 -> 10351
F7: =F6-D7+E7 -> 10351
F8: =F7-D8+E8 -> 10351
F9: =F8-D9+E9 -> 10351
A10: GRAND TOTAL | F10: =F9-D10+E10 -> 10351

Sheet Aswad Sb
A1: LEDGER
A3: Account Holder's Name | D3: Aswad Sb
A4: Pg # | C4: Old Reg(106)
A5: Date | B5: Ref No. | C5: Description | D5: Debit | E5: Credit | F5: Balance
A6: 44571 | C6: PPF + PPF | E6: 270 | F6: =E6-D6 -> 270
A7: 18/1/23 | B7: 306 | C7: PPF | E7: 450 | F7: =E7-D7+F6 -> 720
A8: 44960 | B8: 911 | C8: GAC, CTO | E8: 1000 | F8: =E8-D8+F7 -> 1720
A9: 23/3/23 | B9: 1300 | C9: membrane100G | E9: 10550 | F9: =E9-D9+F8 -> 12270
A10: 45020 | B10: Exp Sh | C10: Cash Deposit | D10: 2000 | F10: =E10-D10+F9 -> 10270
A11: 44931 | B11: Exp Sh | C11: Cash Deposit | D11: 2000 | F11: =E11-D11+F10 -> 8270
A12: 44931 | B12: 1740 | C12: PPF | E12: 300 | F12: =E12-D12+F11 -> 8570
A13: 45177 | B13: E739 | C13: Cash Deposit | D13: 100 | F13: =E13-D13+F12 -> 8470
A14: 45086 | B14: E1092 | C14: Cash Deposit | D14: 1500 | F14: =E14-D14+F13 -> 6970
A15: 45148 | B15: Exp Sh | C15: Cash Deposit | D15: 1500 | F15: =E15-D15+F14 -> 5470
A16: 44968 | B16: E1808 | C16: Cash Deposit | D16: 1700 | F16: =E16-D16+F15 -> 3770
A17: 15/02/24 | B17: F762 | C17: PPF 10" | E17: 400 | F17: =E17-D17+F16 -> 4170
A18: 45385 | B18: Exp Sh | C18: Cash Deposit | D18: 400 | F18: =E18-D18+F17 -> 3770
A19: 45388 | B19: G50 | C19: Cash Deposit | D19: 1500 | F19: =E19-D19+F18 -> 2270
A20: 21/8/24 | B20: G897 | C20: Membrane100G, flow Valve,.. | E20: 9500 | F20: =E20-D20+F19 -> 11770
A21: 45300 | B21: Exp Sh | C21: Cash Deposit | D21: 5000 | F21: =E21-D21+F20 -> 6770
A22: 45361 | B22: Exp Sh | C22: Cash Deposit | D22: 3500 | F22: =E22-D22+F21 -> 3270
A23: 14/10/24 | B23: G1233 | C23: Simple Valve 6mm | E23: 600 | F23: =E23-D23+F22 -> 3870
A24: 15/1/25 | B24: H243 | C24: R.O Filteration | E24: 1700 | F24: =E24-D24+F23 -> 5570
A25: 13/3/25 | C25: Discount | D25: 1000 | F25: =E25-D25+F24 -> 4570
E26: 500 | F26: =E26-D26+F25 -> 5070
C27: Cash Deposit | D27: 2000 | F27: =E27-D27+F26 -> 3070
C28: Discount | D28: 70 | F28: =E28-D28+F27 -> 3000
A29: 45781 | B29: Exp Sh | C29: Cash Deposit | D29: 1500 | F29: =E29-D29+F28 -> 1500
A30: 45842 | B30: H1060 | C30: Flow Wall, Pipe6mm , R.O Set | E30: 2075 | F30: =E30-D30+F29 -> 3575
A31: 45753 | B31: H1944 | C31: PPF 10" | E31: 200 | F31: =E31-D31+F30 -> 3775
A32: 45753 | B32: Exp Sh | C32: Cash Deposit | D32: 1000 | F32: =E32-D32+F31 -> 2775
A33: 45696 | B33: Exp Sh | C33: Cash Deposit | D33: 1000 | F33: =E33-D33+F32 -> 1775
A34: GRAND TOTAL | F34: =E34-D34+F33 -> 1775

Sheet Ahsas Water 
A1: LEDGER
A3: Account Holder's Name | D3: Ahsas Water
A4: Pg # | C4: Old Reg (70)
A5: Date | B5: Ref No. | C5: Description | D5: Debit | E5: Credit | F5: Balance
A6: 45203 | C6: Old Balnace | E6: 100371 | F6: =E6-D6 -> 100371
F7: =E7-D7 -> 0
A8: GRAND TOTAL | F8: =E8-D8 -> 0

Sheet Asia Homeyo Store
A1: LEDGER
A3: Account Holder's Name | D3: Asia Homeo Store
A4: Pg # | C4: Old Reg (64)
A5: Date | B5: Ref No. | C5: Description | D5: Debit | E5: Credit | F5: Balance
A6: 15/06/22 | C6: Old Balnace | E6: 11250 | F6: =E6-D6 -> 11250
F7: =F6-D7+E7 -> 11250
F8: =F7-D8+E8 -> 11250
F9: =F8-D9+E9 -> 11250
A10: GRAND TOTAL | F10: =F9-D10+E10 -> 11250

Sheet Al Subhan Water
A1: LEDGER
A3: Account Holder's Name | D3: Al Subhan Water
A4: Pg # | C4: New Reg (28)
A5: Date | B5: Ref No. | C5: Description | D5: Debit | E5: Credit | F5: Balance
A6: 27/12/23 | B6: F320 | C6: 1.5L Bottle | E6: 10120 | F6: =E6-D6 -> 10120
B7: P | C7: 19L Bottle | D7: 13000 | F7: =F6-D7+E7 -> -2880
A8: 20/01/24 | B8: F521(Rashid) | C8: 1.5L Shoper,.. | E8: 1100 | F8: =F7-D8+E8 -> -1780
C9: adding 19L Bottle | E9: 1780 | F9: =F8-D9+E9 -> 0
F10: =F9-D10+E10 -> 0
F11: =F10-D11+E11 -> 0
A12: GRAND TOTAL | F12: =F11-D12+E12 -> 0

Sheet Barcly Water
A1: LEDGER
A3: Account Holder's Name | D3: Barcly
A4: Pg # | C4: New Reg (137)
A5: Date | B5: Ref No. | C5: Description | D5: Debit | E5: Credit | F5: Balance
C6: Old Balnace | E6: 217850 | F6: 217850
A7: 23/01/24 | B7: F543 | C7: 1.5L Bottle,.. | E7: 25450 | F7: =F6-D7+E7 -> 243300
A8: 24/01/24 | B8: F547 | C8: 1.5L+500 ml fill Pet | D8: 14250 | F8: =F7-D8+E8 -> 229050
A9: 29/01/24 | B9: F584 | C9: 500 ml Btl,.. | E9: 11080 | F9: =F8-D9+E9 -> 240130
A10: 45353 | B10: F618 | C10: 1.5L Bottle,.. | E10: 10450 | F10: =F9-D10+E10 -> 250580
A11: 45445 | B11: F664 | C11: Ca,30mm Caps,. | E11: 12600 | F11: =F10-D11+E11 -> 263180
A12: 45475 | B12: F671 | C12: 500 ml Btl,.. | E12: 42400 | F12: =F11-D12+E12 -> 305580
C13: Shahid Turbine Net Deposit | D13: 20000 | F13: =F12-D13+E13 -> 285580
C14: Uncle Farooq | D14: 125000 | F14: =F13-D14+E14 -> 160580
C15: Cash Dep to Customer Minus From Ledger | D15: 50000 | F15: =F14-D15+E15 -> 110580
A16: 45567 | C16: Net Cash Deposit | D16: 15000 | F16: =F15-D16+E16 -> 95580
C17: Mobile & Commision | D17: 50000 | F17: =F16-D17+E17 -> 45580
C18: Discount | D18: 6580 | F18: =F17-D18+E18 -> 39000
C19: Deposit | D19: 3000 | F19: =F18-D19+E19 -> 36000
A20: 45567 | B20: F690 | C20: Ca,Mg,Na,… | E20: 13500 | F20: =F19-D20+E20 -> 49500
A21: 45598 | B21: F702 | C21: 1.5L Bottle,.. | E21: 26740 | F21: =F20-D21+E21 -> 76240
A22: 15/02/24 | B22: F755 | C22: Ca,500 ml Bottle,.. | E22: 27170 | F22: =F21-D22+E22 -> 103410
A23: 17/02/24 | B23: F774 | C23: Washing Membrane with all chemicals,lab | E23: 5500 | F23: =F22-D23+E23 -> 108910
A24: 18/02/24 | B24: Purchase | C24: Fill Pet | D24: 14500 | F24: =F23-D24+E24 -> 94410
A25: 22/02/24 | B25: F842 | C25: Caps,Shoper,… | E25: 7262 | F25: =F24-D25+E25 -> 101672
C26: 6mm Wire | E26: 8000 | F26: =F25-D26+E26 -> 109672
A27: 29/02/24 | C27: Rcv From Bor | D27: 80000 | F27: =F26-D27+E27 -> 29672
A28: 29/02/24 | B28: F908 | C28: 1.5L Bottle,.. | E28: 6450 | F28: =F27-D28+E28 -> 36122
A29: 45354 | B29: F947 | C29: 1.5L Bottle,.. | E29: 56620 | F29: =F28-D29+E29 -> 92742
A30: 45385 | B30: F958 | C30: 1.5L Bottle,.. | E30: 17620 | F30: =F29-D30+E30 -> 110362
A31: 45446 | B31: F981 | C31: Ca,1.5L Shoper | E31: 3950 | F31: =F30-D31+E31 -> 114312
A32: 45446 | B32: F985 | C32: 500 ml Fill Pet (Purchase) | D32: 7000 | F32: =F31-D32+E32 -> 107312
A33: 45446 | B33: F985 | C33: 500 ml Bottle(Return) | D33: 3698 | F33: =F32-D33+E33 -> 103614
A34: 45446 | B34: F985 | C34: Rickshaw Rent | E34: 600 | F34: =F33-D34+E34 -> 104214
A35: 45476 | B35: F1002 | C35: 1.5L Bottle | E35: 11810 | F35: =F34-D35+E35 -> 116024
A36: 45538 | B36: F1026 | C36: Plant Washing Chemical +Labr | E36: 5500 | F36: =F35-D36+E36 -> 121524
A37: 23/02/24 | C37: Jazz Cash | D37: 7250 | F37: =F36-D37+E37 -> 114274
A38: 14/03/24 | B38: F1070 | C38: Washing with Chemicals+1abr | E38: 6000 | F38: =F37-D38+E38 -> 120274
C39: 19L Bottle(Rehan ) | E39: 5600 | F39: =F38-D39+E39 -> 125874
A40: 45599 | B40: F1039 | C40: 30 mm Caps,.. | E40: 3400 | F40: =F39-D40+E40 -> 129274
A41: 45568 | B41: F1021 | C41: 1.5L Bottle,.. | E41: 10000 | F41: =F40-D41+E41 -> 139274
...

Sheet Bling Water
A1: LEDGER
A3: Account Holder's Name | D3: Bling Water
A4: Pg # | C4: Old Reg(96)
A5: Date | B5: Ref No. | C5: Description | D5: Debit | E5: Credit | F5: Balance
A6: 21/01/24 | B6: F527 | C6: 1.5L Shoper,.. | E6: 12500 | F6: =E6-D6 -> 12500
A7: 21/01/24 | C7: Easypaisa | D7: 12000 | F7: =F6-D7+E7 -> 500
A8: 45475 | B8: F676 | C8: 500 ml Shoper | E8: 5370 | F8: =F7-D8+E8 -> 5870
A9: 45568 | B9: F1029 | C9: 6L Bottle,.. | E9: 7400 | F9: =F8-D9+E9 -> 13270
A10: 45476 | B10: F1030 | C10: 1.5L Bottle | E10: 1190 | F10: =F9-D10+E10 -> 14460
A11: 19/03/24 | B11: Exp Sh | C11: Net Cash Dep | D11: 10000 | F11: =F10-D11+E11 -> 4460
A12: 23/04/24 | B12: F1495 | C12: 1.5L Shoper,.. | E12: 2700 | F12: =F11-D12+E12 -> 7160
A13: 24/04/24 | B13: F1505 | C13: 1.5L, Ozonator new | E13: 98370 | F13: =F12-D13+E13 -> 105530
A14: 24/04/24 | B14: F1505 | C14: IBFT (1000 Cash) | D14: 75000 | F14: =F13-D14+E14 -> 30530
A15: 23/05/24 | B15: F1862 | C15: 19L Pet Bottle,.. | E15: 2300 | F15: =F14-D15+E15 -> 32830
F16: =F15-D16+E16 -> 32830
A17: GRAND TOTAL | F17: =F16-D17+E17 -> 32830

Sheet Bissimillah Senitary 
A1: LEDGER
A3: Account Holder's Name | D3: Bissimillah Senitary
A4: Pg # | C4: Old Reg(154)
A5: Date | B5: Ref No. | C5: Description | D5: Debit | E5: Credit | F5: Balance
A6: 44843 | B6: 3668 | C6: 10" PPF Local | E6: 3624 | F6: 3624
F7: =F6-D7+E7 -> 3624
A8: GRAND TOTAL | F8: =F7-D8+E8 -> 3624

Sheet Berg Water New
A1: LEDGER
A3: Account Holder's Name | D3: Berg Water
A4: Pg # | C4: old Reg(146)
A5: Date | B5: Ref No. | C5: Description | D5: Debit | E5: Credit | F5: Balance
A6: 45694 | B6: H1901 | C6: Remaining Amount of Ampler, Bot Seal, Labour | E6: 7500 | F6: =E6-D6 -> 7500
A7: 22/6/25 | B7: I 69 | C7: Remaining Amount | E7: 7000 | F7: =F6-D7+E7 -> 14500
F12: =F7-D12+E12 -> 14500
A13: GRAND TOTAL | F13: =F12-D13+E13 -> 14500

Sheet Berg Water
A1: LEDGER
A3: Account Holder's Name | D3: Berg Water
A4: Pg # | C4: old Reg(146)
A5: Date | B5: Ref No. | C5: Description | D5: Debit | E5: Credit | F5: Balance
A6: 23/10/23 | C6: Old Balnace | E6: 57984 | F6: =E6 -> 57984
C7: Window work | D7: 13000 | F7: =E7 -> 0
A8: 18/9/24 | B8: G863 | C8: 19L Caps, 19L Lids, 19L Seal | E8: 2750 | F8: =E8 -> 2750
A9: 30/10/24 | B9: G1370 | C9: 19L Caps | E9: 550 | F9: =E9 -> 550
A10: 31/10/24 | B10: G1376 | C10: 19L Caps, 19L Lids, 19L Seal, 19L Bush | E10: 9050 | F10: =E10 -> 9050
A11: 31/10/24 | B11: G1383 | C11: 1.5L - Caps | E11: 3450 | F11: =E11 -> 3450
A12: 45576 | C12: Discount | D12: 15784 | F12: =E12 -> 0
A13: 45576 | C13: Amount Deposited from Machine | D13: 20000 | F13: =E13 -> 0
A14: 16/11/24 | D14: 25000 | F14: =E14 -> 0
A15: 45694 | B15: H1901 | C15: Remaining Amount of Ampler, Bot Seal, Labour | E15: 7500 | F15: =E15 -> 7500
A16: 22/6/25 | B16: I 69 | C16: Remaining Amount | E16: 7000 | F16: =E16 -> 7000
F17: =E17 -> 0
F18: =E18 -> 0
F19: =E19 -> 0
F20: =E20 -> 0
F21: =E21 -> 0
A22: GRAND TOTAL | F22: =E22 -> 0

Sheet Blue Ice 
A1: LEDGER
A3: Account Holder's Name | D3: Blue Ice
A4: Pg #
A5: Date | B5: Ref No. | C5: Description | D5: Debit | E5: Credit | F5: Balance
C6: Opening Balnace | F6: =E6-D6 -> 0
A7: 16/7/24 | B7: G440 | C7: Jumbo hozing, antiscaler | E7: 4050 | F7: =F6-D7+E7 -> 4050
F8: =F7-D8+E8 -> 4050
A9: GRAND TOTAL | F9: =F8-D9+E9 -> 4050

Sheet Bwp Water
A1: LEDGER
A3: Account Holder's Name | D3: Bwp Water
A4: Pg # | C4: Old Reg(109)
A5: Date | B5: Ref No. | C5: Description | D5: Debit | E5: Credit | F5: Balance
A6: 28/5/21 | C6: Old Balnace | E6: 5240 | F6: =E6-D6 -> 5240
A7: 21/11/24 | B7: G1588 | C7: 1.5L + Caps, 1.5L Shoper | E7: 3175 | F7: =F6-D7+E7 -> 8415
A8: 45902 | B8: Exp Sh | C8: Cash deposit | D8: 1000 | F8: =F7-D8+E8 -> 7415
F9: =F8-D9+E9 -> 7415
A10: GRAND TOTAL | F10: =F9-D10+E10 -> 7415

Sheet BWMC
A1: LEDGER
A3: Account Holder's Name | D3: BWMC
A4: Pg # | C4: New Reg (59)
A5: Date | B5: Ref No. | C5: Description | D5: Debit | E5: Credit | F5: Balance
A6: 26/06/23 | B6: E92 | C6: F.M Socket,.. | E6: 13000 | F6: =E6-D6 -> 13000
A7: 45206 | B7: E355 | C7: Gate Valve,… | E7: 2500 | F7: =F6-D7+E7 -> 15500
A8: 45267 | B8: E383 | C8: PPf Slim,.. | E8: 2500 | F8: =F7-D8+E8 -> 18000
A9: 45267 | C9: IBFT | D9: 10000 | F9: =F8-D9+E9 -> 8000
A10: 21/10/23 | C10: IBFT | D10: 7000 | F10: =F9-D10+E10 -> 1000
F11: =F10-D11+E11 -> 1000
A12: GRAND TOTAL | F12: =F11-D12+E12 -> 1000

Sheet Chand Agro
A1: LEDGER
A3: Account Holder's Name | D3: Chand Agro Chemicals
A4: Pg # | C4: New Reg(167)
A5: Date | B5: Ref No. | C5: Description | D5: Debit | E5: Credit | F5: Balance
A6: 44754 | B6: 723 | C6: PPF 10",.. | E6: 1300 | F6: =E6-D6 -> 1300
A7: 44753 | B7: 724 | C7: PPF 10",.. | E7: 1300 | F7: =F6-D7+E7 -> 2600
A8: 44815 | B8: 759 | C8: Carbon Stage,.. | E8: 7700 | F8: =F7-D8+E8 -> 10300
A9: 15/11/22 | B9: 846 | C9: Jambo PPf,.. | E9: 8080 | F9: =F8-D9+E9 -> 18380
A10: 16/11/22 | B10: 857 | C10: Slim PPf,.. | E10: 2500 | F10: =F9-D10+E10 -> 20880
A11: 13/12/22 | B11: 1236 | E11: 10600 | F11: =F10-D11+E11 -> 31480
A12: 20/02/23 | B12: 756 | C12: Half Ton Plant Membrane Washing | E12: 5000 | F12: =F11-D12+E12 -> 36480
A13: 45233 | B13: 1052 | C13: Jambo PPf,.. | E13: 6500 | F13: =F12-D13+E13 -> 42980
A14: 18/03/23 | B14: 1564 | C14: 2 Ton RO Plant | E14: 850000 | F14: =F13-D14+E14 -> 892980
A15: 45082 | B15: 1813 | C15: Jambo PPf | E15: 15000 | F15: =F14-D15+E15 -> 907980
A16: 44964 | B16: E172 | C16: HP Pump4*12,.. | E16: 20000 | F16: =F15-D16+E16 -> 927980
A17: 44966 | B17: E1022 | C17: PPF 10",.. | E17: 1500 | F17: =F16-D17+E17 -> 929480
B18: Solar Bills | C18: Office Solar Plant | E18: 1695700 | F18: =F17-D18+E18 -> 2625180
C19: Usman Sb(House) | E19: 772700 | F19: =F18-D19+E19 -> 3397880
C20: CAC 61DB(Madrasa) | E20: 483100 | F20: =F19-D20+E20 -> 3880980
C21: Ch Sarwar House | E21: 755650 | F21: =F20-D21+E21 -> 4636630
C22: Chand Agro Lab | E22: 97300 | F22: =F21-D22+E22 -> 4733930
C23: Net Metring Factory+Home | E23: 375000 | F23: =F22-D23+E23 -> 5108930
C24: Cheque Rcv | D24: 500000 | F24: =F23-D24+E24 -> 4608930
C25: Cheque Rcv | D25: 500000 | F25: =F24-D25+E25 -> 4108930
C26: Cash Rcv | D26: 400000 | F26: =F25-D26+E26 -> 3708930
C27: Car | D27: 725000 | F27: =F26-D27+E27 -> 2983930
A28: 27/09/23 | B28: F1389 | C28: washing Chemical,.. | E28: 7000 | F28: =F27-D28+E28 -> 2990930
A29: 30/09/23 | B29: F1418 | C29: 500 ml Bottle,.. | E29: 3200 | F29: =F28-D29+E29 -> 2994130
A30: 45056 | B30: F1510 | C30: Chemicals,.. | E30: 13500 | F30: =F29-D30+E30 -> 3007630
A31: 14/11/23 | B31: F1928 | C31: Pump Amparrel,.. | E31: 13500 | F31: =F30-D31+E31 -> 3021130
A32: 18/11/23 | B32: F1951 | C32: Union 1",.. | E32: 1240 | F32: =F31-D32+E32 -> 3022370
A33: 45089 | B33: F112 | C33: PPF 10",.. | E33: 1500 | F33: =F32-D33+E33 -> 3023870
A34: 17/01/24 | B34: F528 | C34: washing Chemical,.. | E34: 9500 | F34: =F33-D34+E34 -> 3033370
A35: 17/01/24 | B35: F528 | C35: Cash Deposit | D35: 10000 | F35: =F34-D35+E35 -> 3023370
C36: Vagan R | D36: 1750000 | F36: =F35-D36+E36 -> 1273370
C37: Discount | D37: 173370 | F37: =F36-D37+E37 -> 1100000
A38: 28/02/24 | B38: F901 | C38: Wasing Chemical+Labr | E38: 9000 | F38: =F37-D38+E38 -> 1109000
A39: 45415 | C39: Baba Khursheed wala jo abhi ana ha | D39: 100000 | F39: =F38-D39+E39 -> 1009000
C40: Cheque Rcv Already | D40: 100000 | F40: =F39-D40+E40 -> 909000
C41: Garu Vagan R | D41: 125000 | F41: =F40-D41+E41 -> 784000
...

Sheet Clean & Clean
A1: LEDGER
A3: Account Holder's Name | D3: Clean & Clean
A4: Pg # | C4: Old Reg(97)
A5: Date | B5: Ref No. | C5: Description | D5: Debit | E5: Credit | F5: Balance
A6: 45088 | C6: Old Balance | E6: 37270 | F6: =E6-D6 -> 37270
F7: =F6-D7+E7 -> 37270
F8: =F7-D8+E8 -> 37270
F9: =F8-D9+E9 -> 37270
F10: =F9-D10+E10 -> 37270
F11: =F10-D11+E11 -> 37270
F12: =F11-D12+E12 -> 37270
A13: GRAND TOTAL | F13: =F12-D13+E13 -> 37270

Sheet Candy Water
A1: LEDGER
A3: Account Holder's Name | D3: Candy Water
A4: Pg # | C4: Old Reg(159)
A5: Date | B5: Ref No. | C5: Description | D5: Debit | E5: Credit | F5: Balance
A6: 23/11/23 | C6: Old Balance | E6: 26950 | F6: =E6-D6 -> 26950
A7: 18/01/24 | B7: F507 | C7: Auto Switch | E7: 8000 | F7: =F6-D7+E7 -> 34950
A8: 29/01/24 | B8: Purchase | C8: 5L Bottle (4000 btl,Rate=32/-) | D8: 128000 | F8: =F7-D8+E8 -> -93050
A9: 45384 | C9: IBFT(Send to customer acc) | E9: 100000 | F9: =F8-D9+E9 -> 6950
A10: 20/02/24 | B10: F816 | C10: Jambo PPF,.. | E10: 7450 | F10: =F9-D10+E10 -> 14400
A11: 45325 | B11: F940 | C11: 19L Caps | E11: 13300 | F11: =F10-D11+E11 -> 27700
A12: 45325 | B12: Exp Sh | C12: Cash Deposit | D12: 20000 | F12: =F11-D12+E12 -> 7700
A13: 19/05/24 | C13: Plant Rep, New Memb ,etc | E13: 91500 | F13: =F12-D13+E13 -> 99200
A14: 45357 | B14: G31 | C14: Mg,Na | E14: 2200 | F14: =F13-D14+E14 -> 101400
A15: 45389 | B15: G341 | C15: Chlorine tab, Mg,Na | E15: 6500 | F15: =F14-D15+E15 -> 107900
A16: 26/9/24 | B16: G1064 | E16: 5500 | F16: =F15-D16+E16 -> 113400
D17: 5000 | F17: =F16-D17+E17 -> 108400
A18: 17/10/24 | B18: G1265 | E18: 4500 | F18: =F17-D18+E18 -> 112900
A19: 45516 | B19: Qazi sb | C19: IBFT received | D19: 50000 | F19: =F18-D19+E19 -> 62900
A20: 18/5/25 | B20: H1692 | C20: Absolute 20", Jumbo PPF | E20: 4750 | F20: =F19-D20+E20 -> 67650
A21: 24/6/2025 | B21: We Recived | C21: 1.5L Bottles 70*30 Packet | D21: 22260 | F21: =F20-D21+E21 -> 45390
C22: 0.5L Bottles 170*15 Packet | D22: 16830 | F22: =F21-D22+E22 -> 28560
B23: We Recived | C23: 6L Bottles 18*120 Packet | D23: 82080 | F23: =F22-D23+E23 -> -53520
C24: 5L bottles 20*30 Packet | D24: 22200 | F24: =F23-D24+E24 -> -75720 | G24: 143370
A25: 45881 | C25: IBFT | E25: 50000 | F25: =F24-D25+E25 -> -25720
A26: 45667 | B26: I 1474 | C26: 30mm caps…. | E26: 23400 | F26: =F25-D26+E26 -> -2320
F27: =F26-D27+E27 -> -2320
F28: =F27-D28+E28 -> -2320
F29: =F28-D29+E29 -> -2320
A30: GRAND TOTAL | F30: =F29-D30+E30 -> -2320

Sheet Crystal Water Bagouchi Pull
A1: LEDGER
A3: Account Holder's Name | D3: Crystal Water Bagouchi Pull
A4: Pg # | C4: Old Reg(94)
A5: Date | B5: Ref No. | C5: Description | D5: Debit | E5: Credit | F5: Balance
A6: 45241 | C6: Old Balance | E6: 5570 | F6: =E6-D6 -> 5570
F7: =F6-D7+E7 -> 5570
A8: GRAND TOTAL | F8: =F7-D8+E8 -> 5570

Sheet Dar e Arqam 
A1: LEDGER
A3: Account Holder's Name | D3: Dar e Arqam
A4: Pg # | C4: New Reg(24)
A5: Date | B5: Ref No. | C5: Description | D5: Debit | E5: Credit | F5: Balance
C6: Opening Balnace | E6: 3050 | F6: =E6-D6 -> 3050
C7: Kids School fees | D7: 3050 | F7: =F6-D7+E7 -> 0
F8: =F7-D8+E8 -> 0
A9: GRAND TOTAL | F9: =F8-D9+E9 -> 0

Sheet 1
A1: LEDGER
A3: Account Holder's Name | D3: Chand Agro
A4: Pg #
A5: Date | B5: Ref No. | C5: Description | D5: Debit | E5: Credit | F5: Balance
C6: Car Vaganr Amount | D6: 1800000 | F6: =E6-D6 -> -1800000
A7: 20/7/2024 | C7: Costomer Ledger | E7: 130540 | F7: =F6-D7+E7 -> -1669460
A8: 45603 | C8: Membranes 8*40 | E8: 250000 | F8: =F7-D8+E8 -> -1419460
A9: 45603 | C9: Media Change with Iron Removal, Gravels+Sand | E9: 25000 | F9: =F8-D9+E9 -> -1394460
A10: 15/5/2025 | C10: Old Balance of Cheque | E10: 736000 | F10: =F9-D10+E10 -> -658460
A11: 30/7/2024 | C11: Remaining Amount from Quotation for Zubair sb Yazman Madarsa | E11: 402820 | F11: =F10-D11+E11 -> -255640
A12: 45893 | C12: Solar Remaning Amount of Usman sb House Yazman | E12: 72000 | F12: =F11-D12+E12 -> -183640
A13: 45660 | B13: H 687 | C13: R.O Filtration | E13: 1500 | F13: =F12-D13+E13 -> -182140
A14: 45660 | B14: H 688 | C14: Solar Labour | E14: 1000 | F14: =F13-D14+E14 -> -181140
A15: 20/4/2025 | B15: H 1280 | C15: Mem 100G, Flow Valve, R.O Filtration System | E15: 7700 | F15: =F14-D15+E15 -> -173440
A16: 45783 | B16: H1965 | C16: 500ml + Caps | E16: 8670 | F16: =F15-D16+E16 -> -164770
C17: Total Payable Amount= 164770 | F17: =F16-D17+E17 -> -164770

Sheet Ever Best
A1: LEDGER
A3: Account Holder's Name | D3: Ever Best
A4: Pg # | C4: Old Reg(104)
A5: Date | B5: Ref No. | C5: Description | D5: Debit | E5: Credit | F5: Balance
A6: 17/04/22 | C6: Old Balnace | E6: 16664 | F6: =E6-D6 -> 16664
F7: =F6-D7+E7 -> 16664
A8: GRAND TOTAL | F8: =F7-D8+E8 -> 16664

Sheet Qari ajmal Sb
A1: LEDGER
A3: Account Holder's Name | D3: Qari Ajmal sb
A4: Pg # | C4: New Reg (60)
A5: Date | B5: Ref No. | C5: Description | D5: Debit | E5: Credit | F5: Balance
C6: Old Balance | E6: 3070 | F6: =E6-D6 -> 3070
A7: 13/02/24 | B7: Exp Sh | C7: Cash Deposit | D7: 1300 | F7: =F6-D7+E7 -> 1770
A8: 25/05/24 | B8: F1881 | C8: 1.5L Botthle | E8: 200 | F8: =F7-D8+E8 -> 1970
A9: 45421 | B9: G644 | C9: 500ml + Caps, 500ml Shoper | E9: 340 | F9: =F8-D9+E9 -> 2310
A10: 45422 | B10: G1139 | C10: Remaining Amount | E10: 515 | F10: =F9-D10+E10 -> 2825
A11: 21/10/24 | B11: G1287 | C11: Remaining Amount | E11: 700 | F11: =F10-D11+E11 -> 3525
A12: 45362 | B12: G1410 | C12: 5L E+ C | E12: 83 | F12: =F11-D12+E12 -> 3608
A13: 16/2/25 | B13: H546 | C13: Remaining Amount | E13: 545 | F13: =F12-D13+E13 -> 4153
A14: 20/2/25 | B14: Exp Sh | C14: Cash Deposit | D14: 550 | F14: =F13-D14+E14 -> 3603
A15: 45720 | B15: H1004 | C15: Remaining Amount | E15: 160 | F15: =F14-D15+E15 -> 3763
A16: 29/4/25 | B16: H1409 | C16: Remaining Amount | E16: 215 | F16: =F15-D16+E16 -> 3978
F17: =F16-D17+E17 -> 3978
F18: =F17-D18+E18 -> 3978
A19: GRAND TOTAL | F19: =F18-D19+E19 -> 3978

Sheet 2
A1: LEDGER
A3: Account Holder's Name | D3: Chand Agro
A4: Pg #
A5: Date | B5: Ref No. | C5: Description | D5: Debit | E5: Credit | F5: Balance
C6: 3 Cars dobule Biomatric | E6: 69000 | F6: =E6-D6 -> 69000
C7: 1 Car Single Biomatric | E7: 27000 | F7: =E7-D7 -> 27000
C8: Total | E8: 92000 | F8: =E8-D8 -> 92000
C9: Number Plates | E9: 150000 | F9: =E9-D9 -> 150000
C10: Biscuts (Chases Number Plates 2 Cars | E10: 50000 | F10: =E10-D10 -> 50000
C11: Total | E11: 296000 | F11: =E11-D11 -> 296000
C12: Total Receivable Amount = 296,000 | F12: =E12-D12 -> 0

Sheet Haji Yousaf Sb
A1: LEDGER
A3: Account Holder's Name | D3: Haji Yousaf Sb
A4: Pg # | C4: New Reg(89)
A5: Date | B5: Ref No. | C5: Description | D5: Debit | E5: Credit | F5: Balance
A6: 45022 | C6: Old Balance | E6: 39838 | F6: =E6-D6 -> 39838
F7: =F6-D7+E7 -> 39838
A8: GRAND TOTAL | F8: =F7-D8+E8 -> 39838

Sheet Honey Water Dr Jameel
A1: LEDGER
A3: Account Holder's Name | D3: Honey Water Dr Jameel
A4: Pg # | C4: New Reg(90)
A5: Date | B5: Ref No. | C5: Description | D5: Debit | E5: Credit | F5: Balance
A6: 28/10/24 | B6: G1354 | E6: 15415 | F6: =E6-D6 -> 15415
D7: 6500 | F7: =F6-D7+E7 -> 8915
A8: 14/6/25 | B8: Exp Sh | C8: Cash deposited | D8: 1250 | F8: =F7-D8+E8 -> 7665
A9: 15/6/25 | B9: H155 | C9: Remaining Amount | E9: 13575 | F9: =F8-D9+E9 -> 21240
A10: 17/6/25 | B10: H200 | C10: 500ml-Caps, 1.5L-Caps, 1.5L Shoper, 500ml Shoper, 30mm Caps | E10: 22087 | F10: =F9-D10+E10 -> 43327
A11: 17/6/25 | B11: Exp Sh | C11: Cash deposited | D11: 10000 | F11: =F10-D11+E11 -> 33327
A12: 17/6/25 | B12: Exp Sh | C12: Cash deposited | D12: 3000 | F12: =F11-D12+E12 -> 30327
A13: 17/6/25 | B13: Exp Sh | C13: Cash deposited | D13: 500 | F13: =F12-D13+E13 -> 29827
A14: 19/6/25 | B14: I 39 | C14: 1.5L Caps, 500ml Caps,1.5L shoper,…. | E14: 14599 | F14: =F13-D14+E14 -> 44426
A15: 19/6/25 | B15: Exp Sh | C15: Cash deposited | D15: 22000 | F15: =F14-D15+E15 -> 22426
A16: 21/6/25 | B16: I59 | C16: 1.5L Shoper, 500ml Seal | E16: 1900 | F16: =F15-D16+E16 -> 24326
A17: 22/6/25 | B17: Exp Sh | C17: Cash deposited | D17: 7600 | F17: =F16-D17+E17 -> 16726
A18: 22/6/25 | B18: Exp Sh | C18: IBFT | D18: 5400 | F18: =F17-D18+E18 -> 11326
A19: 24/6/25 | B19: I 72 | C19: 1.5L Seal, 1.5L Shoper | E19: 2800 | F19: =F18-D19+E19 -> 14126
A20: 24/6/25 | B20: Exp Sh | C20: Cash deposited | D20: 3500 | F20: =F19-D20+E20 -> 10626
A21: 25/6/25 | B21: Exp Sh | C21: IBFT+ Cash | D21: 2800 | F21: =F20-D21+E21 -> 7826
A22: 25/6/25 | B22: I 93 | C22: Remaining Amount | E22: 6932 | F22: =F21-D22+E22 -> 14758
A23: 30/6/25 | B23: Exp Sh | C23: Cash deposited | D23: 6000 | F23: =F22-D23+E23 -> 8758
A24: 45723 | B24: I 209 | C24: 500ml seal, 1.5L Seal | E24: 2600 | F24: =F23-D24+E24 -> 11358
A25: 45876 | B25: I 266 | C25: 30mm Caps, 1.5L Shoper, 500nl Shoper | E25: 4250 | F25: =F24-D25+E25 -> 15608
A26: 45876 | B26: Exp Sh | C26: Cash deposited | D26: 2600 | F26: =F25-D26+E26 -> 13008
A27: 45876 | B27: Exp Sh | C27: IBFT | D27: 6000 | F27: =F26-D27+E27 -> 7008
A28: 45937 | B28: I 299 | C28: Remaining Amount | E28: 4566 | F28: =F27-D28+E28 -> 11574
A29: 45998 | B29: I 327 | C29: 1.5L-Caps, 1.5L Seal, 1.5L Shoper | E29: 7777 | F29: =F28-D29+E29 -> 19351
A30: 45998 | B30: Exp Sh | C30: IBFT + Cash | D30: 4500 | F30: =F29-D30+E30 -> 14851
A31: 16/7/25 | B31: I 374 | C31: Remaining Amount | E31: 5480 | F31: =F30-D31+E31 -> 20331
A32: 15/7/25 | B32: Exp Sh | C32: IBFT | D32: 2700 | F32: =F31-D32+E32 -> 17631
A33: 20/7/25 | B33: I 417 | C33: Cash deposited | D33: 1371 | F33: =F32-D33+E33 -> 16260
A34: 26/7/25 | B34: I 493 | C34: Remaining Amount | E34: 11009 | F34: =F33-D34+E34 -> 27269
A35: 26/7/25 | B35: Exp Sh | C35: Cash deposited | D35: 4300 | F35: =F34-D35+E35 -> 22969
A36: 26/7/25 | B36: Exp Sh | C36: Cash deposited | D36: 2500 | F36: =F35-D36+E36 -> 20469
A37: 28/7/25 | B37: I 524 | C37: 1.5L -Caps, 500ml -Caps, 1.5L Shoper,… | E37: 16929 | F37: =F36-D37+E37 -> 37398
A38: 28/7/25 | B38: Exp Sh | C38: Cash deposited | D38: 8000 | F38: =F37-D38+E38 -> 29398
F39: =F38-D39+E39 -> 29398
F40: =F39-D40+E40 -> 29398
F41: =F40-D41+E41 -> 29398
...

Sheet Hunza Water 
A1: LEDGER
A3: Account Holder's Name | D3: Hunza Water
A4: Pg # | C4: New Reg(73)
A5: Date | B5: Ref No. | C5: Description | D5: Debit | E5: Credit | F5: Balance
A6: 45231 | C6: Old Balance | E6: 8200 | F6: =E6-D6 -> 8200
A7: 45567 | B7: F695 | C7: 19L Caps | E7: 1100 | F7: =F6-D7+E7 -> 9300
A8: 27/02/24 | B8: F883 | C8: Cash Deposit | D8: 800 | F8: =F7-D8+E8 -> 8500
F9: =F8-D9+E9 -> 8500
F10: =F9-D10+E10 -> 8500
F11: =F10-D11+E11 -> 8500
A12: GRAND TOTAL | F12: =F11-D12+E12 -> 8500

Sheet Hayat Royal Water
A1: Ledger | M1: L+B23+A1+A1:F20
A3: Account Holder's Name | D3: Hayat Royal Water | M3: Account Holder's Name | P3: Hayat Royal Water
A4: Pg # | C4: New Reg(178) | M4: Pg # | O4: old Reg(83)
A5: Date | B5: Ref No. | C5: Description | D5: Debit | E5: Credit | F5: Balance | M5: Date | N5: Ref No. | O5: Description | P5: Debit | Q5: Credit | R5: Balance
C6: Old Balance | E6: 91551
M7: 45180 | O7: Old Balance | Q7: 91121 | R7: =Q7-P7 -> 91121
A8: 45394 | B8: G1700 | C8: Remaining amount | F8: =F7-D8+E8 -> 0 | M8: 25/01/24 | N8: F553 | O8: 500 ml Btl,.. | Q8: 6140 | R8: =R7-P8+Q8 -> 97261
A9: 20/11/24 | B9: G1569 | C9: Remaining amount | E9: 4525 | F9: =F8-D9+E9 -> 4525 | M9: 27/01/24 | N9: Exp Sh | O9: Cash Deposit | P9: 4000 | R9: =R8-P9+Q9 -> 93261
A10: 23/11/24 | B10: exp sh | C10: Cash deposited | D10: 1200 | F10: =F9-D10+E10 -> 3325
A11: 45516 | B11: exp sh | C11: Cash deposited | D11: 4000 | F11: =F10-D11+E11 -> -675
A12: 45485 | B12: G1730 | C12: 1.5L- Caps, 30mm Caps, 1.5L Shoper | E12: 2625 | F12: =F11-D12+E12 -> 1950
A13: 45638 | B13: G1761 | C13: Remaining amount | E13: 1415 | F13: =F12-D13+E13 -> 3365
A14: 19/12/24 | B14: G1825 | C14: Remaining amount | E14: 400 | F14: =F13-D14+E14 -> 3765
A15: 23/12/24 | B15: G1861 | C15: 500ml -Caps, 30mm Caps | E15: 1775 | F15: =F14-D15+E15 -> 5540
A16: 29/12/24 | B16: G1912 | C16: 6L+Caps | E16: 1476 | F16: =F15-D16+E16 -> 7016
A17: 31/12/24 | B17: G1926 | C17: 6L+Caps | E17: 1476 | F17: =F16-D17+E17 -> 8492 | M17: 27/01/24 | N17: Exp Sh | O17: Easypaisa | P17: 2000 | R17: =R9-P17+Q17 -> 91261
A18: 31/12/24 | B18: G1929 | C18: 6L+Caps | E18: 738 | F18: =F17-D18+E18 -> 9230 | M18: 28/01/24 | N18: F572 | O18: Cash Deposit | P18: 160 | R18: =R17-P18+Q18 -> 91101
A19: 45658 | B19: H08 | C19: Remaining amount | E19: 1899 | F19: =F18-D19+E19 -> 11129 | M19: 14/02/24 | N19: Exp Sh | O19: Cash Deposit | P19: 1000 | R19: =R18-P19+Q19 -> 90101
A20: 45748 | B20: H28 | C20: 6L+Caps | E20: 738 | F20: =F19-D20+E20 -> 11867 | M20: 21/7/24 | N20: G468 | O20: Remaining amount | Q20: 1015 | R20: =R19-P20+Q20 -> 91116
A21: 45778 | B21: H39 | C21: Cash deposited for Previous Bill | D21: 738 | F21: =F20-D21+E21 -> 11129 | M21: 27/7/24 | N21: G524 | O21: 1.5L - Caps, 500ml - Caps, 30mm Caps, 1.5L Shoper | Q21: 4740 | R21: =R20-P21+Q21 -> 95856
A22: 14/1/25 | B22: H225 | C22: Remaining amount | E22: 1851 | F22: =F21-D22+E22 -> 12980 | M22: 28/7/24 | N22: Exp Sh | P22: 4700 | R22: =R21-P22+Q22 -> 91156
A23: 15/1/25 | B23: H235 | C23: Remaining amount | E23: 515 | F23: =F22-D23+E23 -> 13495 | M23: 28/7/24 | N23: G534 | O23: 1.5L -Caps,1.5L Shoper, 30mm Caps | Q23: 3445 | R23: =R22-P23+Q23 -> 94601
A24: 45871 | B24: H453 | C24: Remaining amount | E24: 1770 | F24: =F23-D24+E24 -> 15265 | M24: 22/6/24 | N24: Exp Sh | O24: Cash Deposit | P24: 1100 | R24: =R23-P24+Q24 -> 93501
A25: 45871 | B25: H455 | C25: 30mm Caps, 19L Caps | E25: 1000 | F25: =F24-D25+E25 -> 16265 | M25: 45329 | N25: Exp Sh | O25: Cash Deposit | P25: 600 | R25: =R24-P25+Q25 -> 92901
A26: 45902 | B26: H465 | C26: Cash deposit as old Balance | D26: 1920 | F26: =F25-D26+E26 -> 14345 | M26: 45359 | N26: Exp Sh | O26: Cash Deposit | P26: 1750 | R26: =R25-P26+Q26 -> 91151
A27: 45993 | C27: NILL 50000 Cash in hand from which H496 Bill paid, credit amount 14345 detected | D27: 14345 | F27: =F26-D27+E27 -> 0 | M27: 45359 | N27: Exp Sh | O27: 500ml- caps | Q27: 1270 | R27: =R26-P27+Q27 -> 92421
A28: 18/3/25 | B28: H849 | C28: Remaining amount | E28: 1000 | F28: =F27-D28+E28 -> 1000
A29: 26/4/25 | B29: H1357 | C29: Remaining amount | E29: 225 | F29: =F28-D29+E29 -> 1225
F30: =F29-D30+E30 -> 1225
F31: =F30-D31+E31 -> 1225
F32: =F31-D32+E32 -> 1225
F33: =F32-D33+E33 -> 1225
F34: =F33-D34+E34 -> 1225
A35: GRAND TOTAL | F35: =F28-D35+E35 -> 1000

Sheet Ice Mountain 
A1: LEDGER
A3: Account Holder's Name | D3: Ice mountain (Zahid Sb)
A4: Pg # | C4: Old Reg(120)
A5: Date | B5: Ref No. | C5: Description | D5: Debit | E5: Credit | F5: Balance
A6: 45176 | C6: Old Balance | E6: 6600 | F6: =E6-D6 -> 6600
F7: =F6-D7+E7 -> 6600
F8: =F7-D8+E8 -> 6600
A9: GRAND TOTAL | F9: =F8-D9+E9 -> 6600

Sheet Just Pure
A1: LEDGER
A3: Account Holder's Name | D3: Just Pure (Salman sab)
A4: Pg # | C4: New Reg(116)
A5: Date | B5: Ref No. | C5: Description | D5: Debit | E5: Credit | F5: Balance
A6: 13/03/24 | B6: F1051 | C6: Memb 4*40 Agro Liks | E6: 88500 | F6: =E6 -> 88500
C7: Plant Wasing Memb,.. | E7: 7500 | F7: =F6-D7+E7 -> 96000
A8: 17/03/24 | B8: F1089 | C8: Gac 10" So Pure (10*400) | E8: 4000 | F8: =F7-D8+E8 -> 100000
A9: 45327 | B9: F1609 | C9: Gac 10" (10*500) | E9: 5000 | F9: =F8-D9+E9 -> 105000
A10: 45631 | B10: F1741 | C10: Gac 10" (02*450) | E10: 900 | F10: =F9-D10+E10 -> 105900
A11: 45297 | B11: G02 | C11: Gac 10" (10*450) | E11: 4500 | F11: =F10-D11+E11 -> 110400
A12: 45391 | B12: G634 | C12: Dosing Pump Repairing | E12: 4000 | F12: =F11-D12+E12 -> 114400
C13: Solar | D13: 114400 | F13: =F12-D13+E13 -> 0
A14: 30/9/24 | B14: G1100 | C14: Flow Valve, Tee (remaining amount) | E14: 700 | F14: =F13-D14+E14 -> 700
A15: 45637 | B15: G1495 | C15: Memb100G (2) | E15: 9000 | F15: =F14-D15+E15 -> 9700
A16: 26/11/24 | B16: G1632 | C16: Membrane 100G (1) | E16: 4500 | F16: =F15-D16+E16 -> 14200
A17: 19/12/24 | B17: G1823 | C17: 6G Tank (1), 150G Membrane (2) | E17: 20500 | F17: =F16-D17+E17 -> 34700
A18: 26/12/24 | B18: G1889 | C18: R.O Set (10Set) | E18: 11000 | F18: =F17-D18+E18 -> 45700
A19: 45689 | B19: H22 | C19: CTO 10", PPF 10" S/P | E19: 800 | F19: =F18-D19+E19 -> 46500
A20: 45778 | B20: H35 | C20: GAC(10),CTO(10),PPF(10) | E20: 14500 | F20: =F19-D20+E20 -> 61000
A21: 45962 | B21: H90 | C21: PPF,CTO Vit, GAC Vit | E21: 2400 | F21: =F20-D21+E21 -> 63400
A22: 29/1/25 | B22: H363 | C22: Chlorine tab, 5L + Caps, 1.5L + Caps | E22: 600 | F22: =F21-D22+E22 -> 64000
A23: 13/2/25 | B23: H508 | C23: Membrane 75G | E23: 3500 | F23: =F22-D23+E23 -> 67500
A24: 45963 | B24: H484 | C24: GAC (2), CTO (2), PPF (2) | E24: 1800 | F24: =F23-D24+E24 -> 69300
A25: 45781 | B25: H1018 | C25: 100G Membrane | E25: 5000 | F25: =F24-D25+E25 -> 74300
A26: 14/4/25 | B26: H1161 | C26: Tank 32G | E26: 5500 | F26: =F25-D26+E26 -> 79800
A27: 14/4/25 | B27: H1164 | C27: High Pressure Pump repairing | E27: 41000 | F27: =F26-D27+E27 -> 120800
